127.0.0.1 - - [20/Nov/2015 02:33:34] "POST / HTTP/1.1" 302 -
kellylpt
<type 'str'>
https://www.instagram.com/kellylpt/
127.0.0.1 - - [20/Nov/2015 02:34:04] "GET /clarifai HTTP/1.1" 500 -
Traceback (most recent call last):
  File "/Library/Python/2.7/site-packages/flask/app.py", line 1836, in __call__
    return self.wsgi_app(environ, start_response)
  File "/Library/Python/2.7/site-packages/flask/app.py", line 1820, in wsgi_app
    response = self.make_response(self.handle_exception(e))
  File "/Library/Python/2.7/site-packages/flask/app.py", line 1403, in handle_exception
    reraise(exc_type, exc_value, tb)
  File "/Library/Python/2.7/site-packages/flask/app.py", line 1817, in wsgi_app
    response = self.full_dispatch_request()
  File "/Library/Python/2.7/site-packages/flask/app.py", line 1477, in full_dispatch_request
    rv = self.handle_user_exception(e)
  File "/Library/Python/2.7/site-packages/flask/app.py", line 1381, in handle_user_exception
    reraise(exc_type, exc_value, tb)
  File "/Library/Python/2.7/site-packages/flask/app.py", line 1475, in full_dispatch_request
    rv = self.dispatch_request()
  File "/Library/Python/2.7/site-packages/flask/app.py", line 1461, in dispatch_request
    return self.view_functions[rule.endpoint](**req.view_args)
  File "/Users/liming/mygithub/SoyLikes/app/views.py", line 22, in images
    keywords = HtmlClarifai2DArray("kellylpt")
  File "/Users/liming/mygithub/SoyLikes/app/HtmlClarifai2DArray.py", line 136, in __init__
    response = urllib2.urlopen(HtmlClarifai2DArray.ig_username(username))
  File "/System/Library/Frameworks/Python.framework/Versions/2.7/lib/python2.7/urllib2.py", line 154, in urlopen
    return opener.open(url, data, timeout)
  File "/System/Library/Frameworks/Python.framework/Versions/2.7/lib/python2.7/urllib2.py", line 431, in open
    response = self._open(req, data)
  File "/System/Library/Frameworks/Python.framework/Versions/2.7/lib/python2.7/urllib2.py", line 449, in _open
    '_open', req)
  File "/System/Library/Frameworks/Python.framework/Versions/2.7/lib/python2.7/urllib2.py", line 409, in _call_chain
    result = func(*args)
  File "/System/Library/Frameworks/Python.framework/Versions/2.7/lib/python2.7/urllib2.py", line 1240, in https_open
    context=self._context)
  File "/System/Library/Frameworks/Python.framework/Versions/2.7/lib/python2.7/urllib2.py", line 1197, in do_open
    raise URLError(err)
URLError: <urlopen error [Errno 8] nodename nor servname provided, or not known>
